Workbook

Sheet Допущения
A1: ДОПУЩЕНИЯ (входные параметры — правьте синие значения)
A2: Параметр | B2: Значение | C2: Комментарий
A3: Общие
A4: Горизонт, лет | B4: 10 | C4: число лет прогноза
A5: Ставка дисконтирования | B5: 0.18 | C5: ключевая + премия за риск
A6: Инфляция (рост цен/затрат) | B6: 0.06 | C6: годовая
A7: Налог ЕСХН | B7: 0.06 | C7: 6% с прибыли
A8: Земля
A9: Участок ИЖС, соток | B9: 15 | C9: под дом
A10: Цена ИЖС, ₽/сотка | B10: 130000 | C10: Томский р-н 100–300 тыс
A11: Сельхозземля, га | B11: 3 | C11: поля/выпас
A12: Цена сельхоз, ₽/га | B12: 400000 | C12: до ~600 тыс/га
A13: CAPEX (постройки/техника)
A14: Дом, м² | B14: 80
A15: Стройка, ₽/м² | B15: 50000 | C15: Томск, каркас/брус
A16: Коммуникации, ₽ | B16: 600000 | C16: скважина, э/э, септик
A17: Коровник, ₽ | B17: 1200000
A18: Сенник/склад, ₽ | B18: 300000
A19: Ограждение/инфра, ₽ | B19: 250000
A20: Техника, ₽ | B20: 900000
A21: Теплицы/огород, ₽ | B21: 200000
A22: Резерв, % от CAPEX | B22: 0.1 | C22: непредвиденное
A23: Поголовье
A24: Коровы, голов | B24: 5
A25: Цена коровы, ₽ | B25: 50000 | C25: Томск 40–53 тыс
A26: Молодняк, голов | B26: 3
A27: Цена молодняка, ₽ | B27: 45000
A28: Козы, голов | B28: 4
A29: Цена козы, ₽ | B29: 12000
A30: Свиньи, голов | B30: 4
A31: Цена свиньи, ₽ | B31: 8000
A32: Куры, голов | B32: 30
A33: Цена курицы, ₽ | B33: 500
A34: Продуктивность и цены
A35: Надой, л/корову/год | B35: 5500
A36: Цена молока, ₽/л | B36: 30 | C36: КФХ-реализация
A37: Доля молока в сыр | B37: 0.3
A38: Выход сыра, кг/л | B38: 0.1
A39: Цена сыра, ₽/кг | B39: 900
A40: Мясо, кг/год | B40: 600
...

Sheet CAPEX
A1: КАПИТАЛЬНЫЕ ВЛОЖЕНИЯ (формулы → лист «Допущения»)
A2: Статья | B2: Сумма, ₽
A3: Земля ИЖС (участок под дом) | B3: =Допущения!$B$9*Допущения!$B$10
A4: Земля сельхоз (поля/выпас) | B4: =Допущения!$B$11*Допущения!$B$12
A5: Дом | B5: =Допущения!$B$14*Допущения!$B$15
A6: Коммуникации | B6: =Допущения!$B$16
A7: Коровник | B7: =Допущения!$B$17
A8: Сенник/склад | B8: =Допущения!$B$18
A9: Ограждение/инфраструктура | B9: =Допущения!$B$19
A10: Техника | B10: =Допущения!$B$20
A11: Теплицы/огород | B11: =Допущения!$B$21
A12: Закупка скота (коровы) | B12: =Допущения!$B$24*Допущения!$B$25
A13: Закупка молодняка | B13: =Допущения!$B$26*Допущения!$B$27
A14: Прочие животные | B14: =Допущения!$B$28*Допущения!$B$29+Допущения!$B$30*Допущения!$B$31+Допущения!$B$32*Допущения!$B$33
A15: Подытог | B15: =SUM(B3:B14)
A16: Резерв | B16: =B15*Допущения!$B$22
A17: ИТОГО CAPEX | B17: =B15+B16

Sheet P&L
A1: ГОДОВОЙ P&L: ВЫРУЧКА − OPEX = EBITDA
A2: ВЫРУЧКА
A3: Молоко (сырое) | B3: =Допущения!$B$24*Допущения!$B$35*(1-Допущения!$B$37)*Допущения!$B$36
A4: Сыр/творог (переработка) | B4: =Допущения!$B$24*Допущения!$B$35*Допущения!$B$37*Допущения!$B$38*Допущения!$B$39
A5: Мясо | B5: =Допущения!$B$40*Допущения!$B$41
A6: Яйца | B6: =Допущения!$B$32*Допущения!$B$42*Допущения!$B$43
A7: Овощи/огород | B7: =Допущения!$B$44
A8: ИТОГО выручка | B8: =SUM(B3:B7)
A10: OPEX
A11: Корма (за вычетом своих полей) | B11: =MAX(0,Допущения!$B$24*Допущения!$B$46-Допущения!$B$11*Допущения!$B$47)
A12: Корм прочим животным | B12: =Допущения!$B$49
A13: Ветеринария/осеменение | B13: =Допущения!$B$24*Допущения!$B$48
A14: ГСМ | B14: =Допущения!$B$50
A15: Электричество | B15: =Допущения!$B$51
A16: Ремонт/прочее | B16: =Допущения!$B$52
A17: Наёмный труд | B17: =Допущения!$B$53
A18: ИТОГО OPEX | B18: =SUM(B11:B17)
A19: EBITDA (выручка − OPEX) | B19: ='P&L'!$B$8-'P&L'!$B$18

Sheet Юнит-экономика
A1: ЮНИТ-ЭКОНОМИКА
A2: Показатель | B2: Значение
A3: Выручка с 1 коровы (молоко), ₽/год | B3: =Допущения!$B$35*Допущения!$B$36
A4: Прямые затраты на 1 корову, ₽/год | B4: =Допущения!$B$46+Допущения!$B$48
A5: Маржа на 1 корову, ₽/год | B5: =Допущения!$B$35*Допущения!$B$36-(Допущения!$B$46+Допущения!$B$48)
A6: Эффект 1 га кормовых, ₽/год | B6: =Допущения!$B$47
A7: Безубыточное стадо vs пост. затраты, голов | B7: =(Допущения!$B$49+Допущения!$B$50+Допущения!$B$51+Допущения!$B$52+Допущения!$B$53)/(Допущения!$B$35*Допущения!$B$36-Допущения!$B$46-Допущения!$B$48)

Sheet Денежный поток (база)
A1: ДЕНЕЖНЫЙ ПОТОК — БАЗОВЫЙ ПРОГНОЗ (формулы)
A2: Год | B2: Свои средства (100%) | C2: Грант КФХ + свои | D2: Льготный кредит
A3: 0 | B3: =-CAPEX!$B$17 | C3: =-MAX(CAPEX!$B$17-Допущения!$B$55,CAPEX!$B$17*Допущения!$B$56) | D3: =-CAPEX!$B$17*(1-Допущения!$B$57) | F3: Платёж по кредиту, ₽/год: | G3: =CAPEX!$B$17*Допущения!$B$57*Допущения!$B$58/(1-(1+Допущения!$B$58)^-Допущения!$B$59)
A4: 1 | B4: =('P&L'!$B$19*(1+Допущения!$B$6)^0)*(1-Допущения!$B$7) | C4: =('P&L'!$B$19*(1+Допущения!$B$6)^0)*(1-Допущения!$B$7) | D4: =('P&L'!$B$19*(1+Допущения!$B$6)^0)*(1-Допущения!$B$7)-IF(1<=Допущения!$B$59,$G3,0)
A5: 2 | B5: =('P&L'!$B$19*(1+Допущения!$B$6)^1)*(1-Допущения!$B$7) | C5: =('P&L'!$B$19*(1+Допущения!$B$6)^1)*(1-Допущения!$B$7) | D5: =('P&L'!$B$19*(1+Допущения!$B$6)^1)*(1-Допущения!$B$7)-IF(2<=Допущения!$B$59,$G3,0)
A6: 3 | B6: =('P&L'!$B$19*(1+Допущения!$B$6)^2)*(1-Допущения!$B$7) | C6: =('P&L'!$B$19*(1+Допущения!$B$6)^2)*(1-Допущения!$B$7) | D6: =('P&L'!$B$19*(1+Допущения!$B$6)^2)*(1-Допущения!$B$7)-IF(3<=Допущения!$B$59,$G3,0)
A7: 4 | B7: =('P&L'!$B$19*(1+Допущения!$B$6)^3)*(1-Допущения!$B$7) | C7: =('P&L'!$B$19*(1+Допущения!$B$6)^3)*(1-Допущения!$B$7) | D7: =('P&L'!$B$19*(1+Допущения!$B$6)^3)*(1-Допущения!$B$7)-IF(4<=Допущения!$B$59,$G3,0)
A8: 5 | B8: =('P&L'!$B$19*(1+Допущения!$B$6)^4)*(1-Допущения!$B$7) | C8: =('P&L'!$B$19*(1+Допущения!$B$6)^4)*(1-Допущения!$B$7) | D8: =('P&L'!$B$19*(1+Допущения!$B$6)^4)*(1-Допущения!$B$7)-IF(5<=Допущения!$B$59,$G3,0)
A9: 6 | B9: =('P&L'!$B$19*(1+Допущения!$B$6)^5)*(1-Допущения!$B$7) | C9: =('P&L'!$B$19*(1+Допущения!$B$6)^5)*(1-Допущения!$B$7) | D9: =('P&L'!$B$19*(1+Допущения!$B$6)^5)*(1-Допущения!$B$7)-IF(6<=Допущения!$B$59,$G3,0)
A10: 7 | B10: =('P&L'!$B$19*(1+Допущения!$B$6)^6)*(1-Допущения!$B$7) | C10: =('P&L'!$B$19*(1+Допущения!$B$6)^6)*(1-Допущения!$B$7) | D10: =('P&L'!$B$19*(1+Допущения!$B$6)^6)*(1-Допущения!$B$7)-IF(7<=Допущения!$B$59,$G3,0)
A11: 8 | B11: =('P&L'!$B$19*(1+Допущения!$B$6)^7)*(1-Допущения!$B$7) | C11: =('P&L'!$B$19*(1+Допущения!$B$6)^7)*(1-Допущения!$B$7) | D11: =('P&L'!$B$19*(1+Допущения!$B$6)^7)*(1-Допущения!$B$7)-IF(8<=Допущения!$B$59,$G3,0)
A12: 9 | B12: =('P&L'!$B$19*(1+Допущения!$B$6)^8)*(1-Допущения!$B$7) | C12: =('P&L'!$B$19*(1+Допущения!$B$6)^8)*(1-Допущения!$B$7) | D12: =('P&L'!$B$19*(1+Допущения!$B$6)^8)*(1-Допущения!$B$7)-IF(9<=Допущения!$B$59,$G3,0)
A13: 10 | B13: =('P&L'!$B$19*(1+Допущения!$B$6)^9)*(1-Допущения!$B$7) | C13: =('P&L'!$B$19*(1+Допущения!$B$6)^9)*(1-Допущения!$B$7) | D13: =('P&L'!$B$19*(1+Допущения!$B$6)^9)*(1-Допущения!$B$7)-IF(10<=Допущения!$B$59,$G3,0)
A15: NPV | B15: =B3+NPV(Допущения!$B$5,B4:B13) | C15: =C3+NPV(Допущения!$B$5,C4:C13) | D15: =D3+NPV(Допущения!$B$5,D4:D13)
A16: IRR | B16: =IFERROR(IRR(B3:B13),"—") | C16: =IFERROR(IRR(C3:C13),"—") | D16: =IFERROR(IRR(D3:D13),"—")
A17: Свои вложения (год 0), ₽ | B17: =-B3 | C17: =-C3 | D17: =-D3

Sheet Прогноз (3 сценария)
A1: ПРОГНОЗЫ: ПЕССИМИСТИЧНЫЙ / БАЗОВЫЙ / ОПТИМИСТИЧНЫЙ
A2: Множители сценариев
A3: Драйвер | B3: Пессимистичный | C3: Базовый | D3: Оптимистичный
A4: Цена молока | B4: 0.8 | C4: 1 | D4: 1.2
A5: Надой | B5: 0.85 | C5: 1 | D5: 1.15
A6: Стоимость кормов | B6: 1.2 | C6: 1 | D6: 0.85
A7: CAPEX | B7: 1.15 | C7: 1 | D7: 0.9
A8: Выручка овощи | B8: 0.7 | C8: 1 | D8: 1.3
A9: Цена мяса | B9: 0.85 | C9: 1 | D9: 1.15
A10: Δ ставки дисконт. | B10: 0.04 | C10: 0 | D10: -0.03
A12: Показатель | B12: Пессимистичный | C12: Базовый | D12: Оптимистичный
A13: CAPEX, ₽ | B13: 14016200 | C13: 12188000 | D13: 10969200
A14: Выручка, ₽/год | B14: 1475425 | C14: 1880800 | D14: 2320825
A15: OPEX, ₽/год | B15: 590000 | C15: 530000 | D15: 485000
A16: EBITDA, ₽/год | B16: 885425 | C16: 1350800 | D16: 1835825
A17: Свои средства (100%)
A18: Окупаемость, лет | B18: — | C18: 7.8013188 | D18: 5.5375584
A19: NPV, ₽ | B19: -10089651 | C19: -5227297 | D19: -282862
A20: IRR | B20: -0.039129122 | C20: 0.05667617 | D20: 0.14383036
A21: Грант КФХ + свои
A22: Окупаемость, лет | B22: 8.5868887 | C22: 5.0178258 | D22: 3.2312742
A23: NPV, ₽ | B23: -5089651 | C23: -227297 | D23: 4717138
A24: IRR | B24: 0.034156041 | C24: 0.17188939 | D24: 0.31582023
A25: Льготный кредит
A26: Окупаемость, лет | B26: — | C26: 8.570438 | D26: 5.2960701
A27: NPV, ₽ | B27: -6643912 | C27: -2731494 | D27: 1566526
A28: IRR | B28: -0.099330694 | C28: 0.061318384 | D28: 0.21321639

Sheet Чувствительность
A1: ЧУВСТВИТЕЛЬНОСТЬ NPV (схема «Грант КФХ», базовый прогноз)
A2: Строки — цена молока, столбцы — стоимость кормов. Значения: NPV, ₽.
A4: Молоко \ Корма | B4: -20% | C4: -10% | D4: +0% | E4: +10% | F4: +20%
A5: -20% | B5: -513290 | C5: -667881 | D5: -822471 | E5: -977062 | F5: -1131653
A6: -10% | B6: -215703 | C6: -370294 | D6: -524884 | E6: -679475 | F6: -834066
A7: +0% | B7: 81884 | C7: -72707 | D7: -227297 | E7: -381888 | F7: -536479
A8: +10% | B8: 379471 | C8: 224880 | D8: 70290 | E8: -84301 | F8: -238892
A9: +20% | B9: 677058 | C9: 522467 | D9: 367877 | E9: 213286 | F9: 58695

Sheet Источники
A1: ИСТОЧНИКИ ДАННЫХ (Томск, 2026)
A2: Параметр | B2: Источник
A3: Участки ИЖС Томский р-н (100–300 тыс/сотка) | B3: tomsk.cian.ru / tomsk.sibdom.ru / m2.ru
A4: Сельхозземля (до ~600 тыс/га) | B4: tomsk.move.ru / tomsk.cian.ru
A5: Строительство дома (Томск) | B5: dom-stroy70.ru / tomsk.kamprok.ru
A6: Закупочная цена молока (выс. сорт ~40 ₽/л, КФХ меньше) | B6: vtomske.ru / souzmoloko.ru
A7: Цена КРС (дойная 40–53 тыс ₽) | B7: sobut.ru / agroserver.ru
A8: Грант «Агростартап» Томск (3–6 млн, до 7 на КРС) | B8: svetich.info / svoefermerstvo.ru
A9: Льготный кредит АПК (ставка до 5%, срок до 7 лет) | B9: rshb.ru / svoefermerstvo.ru
A11: Цены ориентировочные (диапазоны рынка). Перед решением проверьте по конкретному участку.
